Traceback (most recent call last):
  File "/Users/Emman/opt/anaconda3/envs/env-jupyterbook/lib/python3.7/site-packages/jupyter_cache/executors/utils.py", line 56, in single_nb_execution
    record_timing=False,
  File "/Users/Emman/opt/anaconda3/envs/env-jupyterbook/lib/python3.7/site-packages/nbclient/client.py", line 1082, in execute
    return NotebookClient(nb=nb, resources=resources, km=km, **kwargs).execute()
  File "/Users/Emman/opt/anaconda3/envs/env-jupyterbook/lib/python3.7/site-packages/nbclient/util.py", line 74, in wrapped
    return just_run(coro(*args, **kwargs))
  File "/Users/Emman/opt/anaconda3/envs/env-jupyterbook/lib/python3.7/site-packages/nbclient/util.py", line 53, in just_run
    return loop.run_until_complete(coro)
  File "/Users/Emman/opt/anaconda3/envs/env-jupyterbook/lib/python3.7/asyncio/base_events.py", line 587, in run_until_complete
    return future.result()
  File "/Users/Emman/opt/anaconda3/envs/env-jupyterbook/lib/python3.7/site-packages/nbclient/client.py", line 536, in async_execute
    cell, index, execution_count=self.code_cells_executed + 1
  File "/Users/Emman/opt/anaconda3/envs/env-jupyterbook/lib/python3.7/site-packages/nbclient/client.py", line 827, in async_execute_cell
    self._check_raise_for_error(cell, exec_reply)
  File "/Users/Emman/opt/anaconda3/envs/env-jupyterbook/lib/python3.7/site-packages/nbclient/client.py", line 735, in _check_raise_for_error
    raise CellExecutionError.from_cell_and_msg(cell, exec_reply['content'])
nbclient.exceptions.CellExecutionError: An error occurred while executing the following cell:
------------------
timesheet.drop(timesheet.columns[[5, 6, 7]], axis = 1, inplace = True) 
timesheet.head()
------------------

[0;31m---------------------------------------------------------------------------[0m
[0;31mIndexError[0m                                Traceback (most recent call last)
[0;32m<ipython-input-33-aa12a0168ad4>[0m in [0;36m<module>[0;34m[0m
[0;32m----> 1[0;31m [0mtimesheet[0m[0;34m.[0m[0mdrop[0m[0;34m([0m[0mtimesheet[0m[0;34m.[0m[0mcolumns[0m[0;34m[[0m[0;34m[[0m[0;36m5[0m[0;34m,[0m [0;36m6[0m[0;34m,[0m [0;36m7[0m[0;34m][0m[0;34m][0m[0;34m,[0m [0maxis[0m [0;34m=[0m [0;36m1[0m[0;34m,[0m [0minplace[0m [0;34m=[0m [0;32mTrue[0m[0;34m)[0m[0;34m[0m[0;34m[0m[0m
[0m[1;32m      2[0m [0mtimesheet[0m[0;34m.[0m[0mhead[0m[0;34m([0m[0;34m)[0m[0;34m[0m[0;34m[0m[0m

[0;32m~/opt/anaconda3/envs/env-jupyterbook/lib/python3.7/site-packages/pandas/core/indexes/base.py[0m in [0;36m__getitem__[0;34m(self, key)[0m
[1;32m   4109[0m             [0mkey[0m [0;34m=[0m [0mnp[0m[0;34m.[0m[0masarray[0m[0;34m([0m[0mkey[0m[0;34m,[0m [0mdtype[0m[0;34m=[0m[0mbool[0m[0;34m)[0m[0;34m[0m[0;34m[0m[0m
[1;32m   4110[0m [0;34m[0m[0m
[0;32m-> 4111[0;31m         [0mresult[0m [0;34m=[0m [0mgetitem[0m[0;34m([0m[0mkey[0m[0;34m)[0m[0;34m[0m[0;34m[0m[0m
[0m[1;32m   4112[0m         [0;32mif[0m [0;32mnot[0m [0mis_scalar[0m[0;34m([0m[0mresult[0m[0;34m)[0m[0;34m:[0m[0;34m[0m[0;34m[0m[0m
[1;32m   4113[0m             [0;32mif[0m [0mnp[0m[0;34m.[0m[0mndim[0m[0;34m([0m[0mresult[0m[0;34m)[0m [0;34m>[0m [0;36m1[0m[0;34m:[0m[0;34m[0m[0;34m[0m[0m

[0;31mIndexError[0m: index 5 is out of bounds for axis 0 with size 5
IndexError: index 5 is out of bounds for axis 0 with size 5

